error
   MK94.Assert.NUnit.Test.Tests.<>c.<ExceptionTest>b__2_0()
   at System.Threading.Tasks.Task`1.InnerInvoke()
   at System.Threading.Tasks.Task.<>c.<.cctor>b__274_0(Object obj)
   at System.Threading.ExecutionContext.RunFromThreadPoolDispatchLoop(Thread threadPoolThread, ExecutionContext executionContext, ContextCallback callback, Object state)
--- End of stack trace from previous location where exception was thrown ---
   at System.Threading.ExecutionContext.RunFromThreadPoolDispatchLoop(Thread threadPoolThread, ExecutionContext executionContext, ContextCallback callback, Object state)
   at System.Threading.Tasks.Task.ExecuteWithThreadLocal(Task& currentTaskSlot, Thread threadPoolThread)
--- End of stack trace from previous location where exception was thrown ---
   MK94.Assert.Assert.MatchesException[T](Task asyncInstance, String step)